[2024-05-24T03:06:28.700+0000] {taskinstance.py:1157} INFO - Dependencies all met for dep_context=non-requeueable deps ti=<TaskInstance: minio_python_task.execute_teste_py manual__2024-05-24T03:06:27.875898+00:00 [queued]>
[2024-05-24T03:06:28.714+0000] {taskinstance.py:1157} INFO - Dependencies all met for dep_context=requeueable deps ti=<TaskInstance: minio_python_task.execute_teste_py manual__2024-05-24T03:06:27.875898+00:00 [queued]>
[2024-05-24T03:06:28.714+0000] {taskinstance.py:1359} INFO - Starting attempt 1 of 2
[2024-05-24T03:06:28.733+0000] {taskinstance.py:1380} INFO - Executing <Task(PythonOperator): execute_teste_py> on 2024-05-24 03:06:27.875898+00:00
[2024-05-24T03:06:28.738+0000] {standard_task_runner.py:57} INFO - Started process 824 to run task
[2024-05-24T03:06:28.741+0000] {standard_task_runner.py:84} INFO - Running: ['***', 'tasks', 'run', 'minio_python_task', 'execute_teste_py', 'manual__2024-05-24T03:06:27.875898+00:00', '--job-id', '31', '--raw', '--subdir', 'DAGS_FOLDER/dag_teste/teste_***.py', '--cfg-path', '/tmp/tmpjggay3ts']
[2024-05-24T03:06:28.742+0000] {standard_task_runner.py:85} INFO - Job 31: Subtask execute_teste_py
[2024-05-24T03:06:28.808+0000] {task_command.py:415} INFO - Running <TaskInstance: minio_python_task.execute_teste_py manual__2024-05-24T03:06:27.875898+00:00 [running]> on host 7b5dece41aaf
[2024-05-24T03:06:28.929+0000] {taskinstance.py:1660} INFO - Exporting env vars: AIRFLOW_CTX_DAG_OWNER='***' AIRFLOW_CTX_DAG_ID='minio_python_task' AIRFLOW_CTX_TASK_ID='execute_teste_py' AIRFLOW_CTX_EXECUTION_DATE='2024-05-24T03:06:27.875898+00:00' AIRFLOW_CTX_TRY_NUMBER='1' AIRFLOW_CTX_DAG_RUN_ID='manual__2024-05-24T03:06:27.875898+00:00'
[2024-05-24T03:06:28.933+0000] {taskinstance.py:1935} ERROR - Task failed with exception
Traceback (most recent call last):
  File "/home/airflow/.local/lib/python3.11/site-packages/airflow/operators/python.py", line 192, in execute
    return_value = self.execute_callable()
                   ^^^^^^^^^^^^^^^^^^^^^^^
  File "/home/airflow/.local/lib/python3.11/site-packages/airflow/operators/python.py", line 209, in execute_callable
    return self.python_callable(*self.op_args, **self.op_kwargs)
           ^^^^^^^^^^^^^^^^^^^^^^^^^^^^^^^^^^^^^^^^^^^^^^^^^^^^^
  File "/opt/airflow/dags/dag_teste/teste_airflow.py", line 7, in execute_python_file
    exec(open("/opt/airflow/dags/jedi_files/main_script.py").read())
         ^^^^^^^^^^^^^^^^^^^^^^^^^^^^^^^^^^^^^^^^^^^^^^^^^^^
FileNotFoundError: [Errno 2] No such file or directory: '/opt/airflow/dags/jedi_files/main_script.py'
[2024-05-24T03:06:28.947+0000] {taskinstance.py:1398} INFO - Marking task as UP_FOR_RETRY. dag_id=minio_python_task, task_id=execute_teste_py, execution_date=20240524T030627, start_date=20240524T030628, end_date=20240524T030628
[2024-05-24T03:06:28.959+0000] {standard_task_runner.py:104} ERROR - Failed to execute job 31 for task execute_teste_py ([Errno 2] No such file or directory: '/opt/airflow/dags/jedi_files/main_script.py'; 824)
[2024-05-24T03:06:29.001+0000] {local_task_job_runner.py:228} INFO - Task exited with return code 1
[2024-05-24T03:06:29.038+0000] {taskinstance.py:2776} INFO - 0 downstream tasks scheduled from follow-on schedule check
