[2024-05-24T03:25:34.694+0000] {taskinstance.py:1157} INFO - Dependencies all met for dep_context=non-requeueable deps ti=<TaskInstance: minio_python_task.execute_teste_py manual__2024-05-24T03:25:33.330073+00:00 [queued]>
[2024-05-24T03:25:34.714+0000] {taskinstance.py:1157} INFO - Dependencies all met for dep_context=requeueable deps ti=<TaskInstance: minio_python_task.execute_teste_py manual__2024-05-24T03:25:33.330073+00:00 [queued]>
[2024-05-24T03:25:34.715+0000] {taskinstance.py:1359} INFO - Starting attempt 1 of 2
[2024-05-24T03:25:34.734+0000] {taskinstance.py:1380} INFO - Executing <Task(PythonOperator): execute_teste_py> on 2024-05-24 03:25:33.330073+00:00
[2024-05-24T03:25:34.739+0000] {standard_task_runner.py:57} INFO - Started process 1564 to run task
[2024-05-24T03:25:34.742+0000] {standard_task_runner.py:84} INFO - Running: ['***', 'tasks', 'run', 'minio_python_task', 'execute_teste_py', 'manual__2024-05-24T03:25:33.330073+00:00', '--job-id', '43', '--raw', '--subdir', 'DAGS_FOLDER/dag_teste/teste_***.py', '--cfg-path', '/tmp/tmp1xjndcui']
[2024-05-24T03:25:34.744+0000] {standard_task_runner.py:85} INFO - Job 43: Subtask execute_teste_py
[2024-05-24T03:25:34.812+0000] {task_command.py:415} INFO - Running <TaskInstance: minio_python_task.execute_teste_py manual__2024-05-24T03:25:33.330073+00:00 [running]> on host 7b5dece41aaf
[2024-05-24T03:25:34.965+0000] {taskinstance.py:1660} INFO - Exporting env vars: AIRFLOW_CTX_DAG_OWNER='***' AIRFLOW_CTX_DAG_ID='minio_python_task' AIRFLOW_CTX_TASK_ID='execute_teste_py' AIRFLOW_CTX_EXECUTION_DATE='2024-05-24T03:25:33.330073+00:00' AIRFLOW_CTX_TRY_NUMBER='1' AIRFLOW_CTX_DAG_RUN_ID='manual__2024-05-24T03:25:33.330073+00:00'
[2024-05-24T03:25:34.969+0000] {logging_mixin.py:151} INFO - Iniciando a instalação do Java...
[2024-05-24T03:25:34.970+0000] {taskinstance.py:1935} ERROR - Task failed with exception
Traceback (most recent call last):
  File "<string>", line 32, in install_java
NameError: name 'subprocess' is not defined

During handling of the above exception, another exception occurred:

Traceback (most recent call last):
  File "/home/airflow/.local/lib/python3.11/site-packages/airflow/operators/python.py", line 192, in execute
    return_value = self.execute_callable()
                   ^^^^^^^^^^^^^^^^^^^^^^^
  File "/home/airflow/.local/lib/python3.11/site-packages/airflow/operators/python.py", line 209, in execute_callable
    return self.python_callable(*self.op_args, **self.op_kwargs)
           ^^^^^^^^^^^^^^^^^^^^^^^^^^^^^^^^^^^^^^^^^^^^^^^^^^^^^
  File "/opt/airflow/dags/dag_teste/teste_airflow.py", line 7, in execute_python_file
    exec(open("/opt/airflow/dags/jedi_files/print.py").read())
  File "<string>", line 72, in <module>
  File "<string>", line 36, in install_java
NameError: name 'subprocess' is not defined
[2024-05-24T03:25:34.981+0000] {taskinstance.py:1398} INFO - Marking task as UP_FOR_RETRY. dag_id=minio_python_task, task_id=execute_teste_py, execution_date=20240524T032533, start_date=20240524T032534, end_date=20240524T032534
[2024-05-24T03:25:34.992+0000] {standard_task_runner.py:104} ERROR - Failed to execute job 43 for task execute_teste_py (name 'subprocess' is not defined; 1564)
[2024-05-24T03:25:35.003+0000] {local_task_job_runner.py:228} INFO - Task exited with return code 1
[2024-05-24T03:25:35.039+0000] {taskinstance.py:2776} INFO - 0 downstream tasks scheduled from follow-on schedule check
